# 자바의 신

### 예외란?

자바에는 예외는 우리가 예상한, 혹은 예상치도 못한 일이 발생 하는 것을 미리 예견하고 안전장치를 하는 것이다. <br>
자바에서는 예상을 했던 , 안했든 예외적인 일이 발생하면 "예외" 라는 것을 던져버린다. <br>
예를 들어 null 인 객체에 메소드를 호출하던지, 배열의 길이보다 긴 값을 호출하던지 등등 예외상황이 오면 에외를 던진다.

---
### try - catch

설명하기 전에 배열 밖에 있는 값을 읽으려고 할 때 오류를 확인해보자.

#### <div id = "arrayException"> ArrayException </div>
~~~java
public class ExceptionEx {
    public void arrayOutOfBounds() {
        int[] arr = new int[5];
        System.out.println(arr[5]);
    }
    public static void main(String[] args) {
        ExceptionEx ex = new ExceptionEx();
        ex.arrayOutOfBounds();
    }
}
~~~

#### 실행결과

> <span style = "color : red"> at ExceptionEx.arrayOutOfBounds(ExceptionEx.java:4) </span>

이렇게 ArrayIndexOutOfBoundsException 오류가 났는데 이것은 배열의 범위 밖에 있는 위치를 요청한 예외 라는 것이다.<br>
컴파일할 때 에러메세지가 생기는 것처럼 예외의 첫 줄에는 어떤 예외가 발생했는지 출력된다.

그렇다면 예외처리를 해서 예외 메세지를 발생시키지 않도록 해보자.

위의[코드](#arrayException)에서 해당 부분을 수정해보자.

~~~java
public void arrayOutOfBounds() {
    int[] arr = new int[5];
    try{
        System.out.println(arr[5]);
    }catch(Exception e){
        System.out.println("Error");
    }
    System.out.println("finish");
}
~~~

#### 실행결과

> Error

예외가 발생하는 부분을 try-catch 로 묶어주면 정상적으로 컴파일도 되고 실행도 정상적으로 된다.

**Q.** try 부분에서 에러가 발생되면 catch로 넘어가는 것을 확인했다. 그렇다면 try에서 오류가 없는 부분도 있다면 출력이 될까? <br>

~~~java
public void arrayOutOfBoundsTryCatch() {
    int[] arr = new int[5];
    try {
        System.out.println(arr[5]);
        System.out.println("try code");
    } catch (Exception e) {
        System.err.println("Exception");
    }
    System.out.println("finish");
}
~~~

#### 실행결과

> <span style = "color : red"> Exception </span> <br>
> finish

try문에 오류를 발견하는 즉시 catch로 넘어가 그 뒤에 있는 코드는 실행되지 않는 걸 확인할 수 있다. <br>
그리고, System.err.println 을 사용하면 글씨가 빨간색으로 나오게 된다.

#### 정리해보면

- try-catch 에서 예외가 발생하지 않은 경우
    - try 내에 있는 모든 문장이 실행되고 try-catch 문장 이후에 내용이 실행된다.
    
- try-catch 에서 예외가 발생하는 경우
    - try 내에서 예외가 발생한 이후의 문장들은 실행되지 않는다. <br>
    catch 내에 있는 문장은 반드시 실행되고, try-catch 문장 이후의 내용이 실행된다.
      
---

**Q.** catch 문에서 try 문에 선언한 변수를 사용할 수 있을까? <br>

위의[코드](#arrayException)에서 메소드를 추가해 보자.
~~~java
public void checkVariable() {
        try {
            int[] arr = new int[5];
            System.out.println(arr[5]);
        } catch (Exception e) {
            System.out.println(arr.length);
        }
        System.out.println("finish");
    }
~~~

#### 실행결과

<span style = "color : red"> java: cannot find symbol <br>
symbol:   variable arr <br>
location: class ExceptionEx <br>